<?xml version="1.0"?>

<!-- Last modified 9 March 2024 -->
<!-- by Fabian Kung -->

<robot name="fk_wheelrobot" xmlns:xacro="http://ros.org/wiki/xacro">

    <material name="grey">
        <color rgba="0.5 0.5 0.5 1" />
    </material>

    <material name="blue">
        <color rgba="0 0 0.5 1" />
    </material>
    
    <material name="lightgrey">
        <color rgba="0.8 0.8 0.8 1" />
    </material>    
    
    <material name="darkgrey">
        <color rgba="0.2 0.2 0.2 1" />
    </material>       
     
    <material name="white">
        <color rgba="1 1 1 1" />
    </material> 
    
    <material name="yellow">
        <color rgba="1 1 0 1" />
    </material>      
    
    <!-- base_link (required for Nav2) -->
    <link name="base_link">
        <visual>
            <geometry>
                <box size="0.145 0.1 0.085" />
            </geometry>
            <origin xyz="0 0 0" rpy="0 0 0" />
            <material name="blue" />
        </visual>
    </link>
    
    <!-- base_footprint (projection of base_link on the ground) -->
    <!-- Required for Nav2 and Rviz2 -->
    <link name="base_footprint"/>   
    
    <joint name="base_joint" type="fixed">
        <parent link="base_footprint"/>
        <child link="base_link"/>
        <origin xyz="0 0 0.0645" rpy="0 0 0"/>
    </joint>    
     
   <!-- Top_body -->
    <link name="top_link">
        <visual>
            <geometry>
                <box size="0.132 0.160 0.028" />
            </geometry>
            <origin xyz="0 0 0" rpy="0 0 0" />
            <material name="blue" />
        </visual>
    </link>  
    
    <!-- The z offset is 0.5*(base_link.height + top_link.height)-->
    <joint name="base_top_joint" type="fixed">
        <parent link="base_link"/>
        <child link="top_link"/>
        <origin xyz="0 0 0.0565" rpy="0 0 0"/>
    </joint>          
     
    <!-- Wheels (2 differential wheels) -->
    <link name="left_wheel">
        <visual>
            <geometry>
                <cylinder radius="0.042" length="0.0385"/>
            </geometry>
            <origin xyz="0 0 0" rpy="1.57 0 0" />
            <material name="darkgrey" />
        </visual>
    </link>

    <joint name="base_left_wheel_joint" type="continuous">
        <parent link="base_link"/>
        <child link="left_wheel"/>
        <origin xyz="-0.0425 0.078 -0.0243" rpy="0 0 0"/>
        <axis xyz="0 1 0"/>
    </joint>
        
    <link name="right_wheel">
        <visual>
            <geometry>
                <cylinder radius="0.042" length="0.0385"/>
            </geometry>
            <origin xyz="0 0 0" rpy="1.57 0 0" />
            <material name="darkgrey" />
        </visual>
    </link>    

    <joint name="base_right_wheel_joint" type="continuous">
        <parent link="base_link"/>
        <child link="right_wheel"/>
        <origin xyz="-0.0425 -0.078 -0.0243" rpy="0 0 0"/>
        <axis xyz="0 1 0"/>
    </joint>
    
    <!-- Castor wheel to keep the balance -->
    <link name="caster_wheel">
        <visual>
            <geometry>
                <sphere radius="0.011"/>
            </geometry>
            <origin xyz="0 0 0" rpy="0 0 0" />
            <material name="white" />
        </visual>
    </link>  
    
    <joint name="base_caster_wheel_joint" type="fixed">
        <parent link="base_link"/>
        <child link="caster_wheel"/>
        <origin xyz="0.0525 0 -0.0540" rpy="0 0 0"/>
    </joint>  
             
    <!-- Various sensors link -->
    <!-- Lidar sensor (required for Nav2) -->
    <link name="base_scan_link">
        <visual>
            <geometry>
                <cylinder radius="0.017" length="0.012"/>
            </geometry>
            <origin xyz="0 0 0" rpy="0 0 0" />
            <material name="yellow" />
        </visual>
    </link>    
    
    <joint name="base_scan_joint" type="fixed">
        <parent link="base_link"/>
        <child link="base_scan_link"/>
        <origin xyz="0.0 0.0 0.1095" rpy="0 0 0"/>
        <axis xyz="0 0 1"/>    
    </joint>

    <!-- Range sensors link -->
    <link name="right_rsen_link">
        <visual>
            <geometry>
                <box size="0.013 0.014 0.03" />
            </geometry>
            <origin xyz="0 0 0" rpy="0 0 0" />
            <material name="yellow" />
        </visual>
    </link>    

    <joint name="right_rsen_joint" type="fixed">
        <parent link="base_link"/>
        <child link="right_rsen_link"/>
        <origin xyz="0.045 -0.065 0.015" rpy="0 0 -1.571"/>
    </joint>
        
    <link name="left_rsen_link">
        <visual>
            <geometry>
                <box size="0.013 0.014 0.03" />
            </geometry>
            <origin xyz="0 0 0" rpy="0 0 0" />
            <material name="yellow" />
        </visual>
    </link>    

    <joint name="left_rsen_joint" type="fixed">
        <parent link="base_link"/>
        <child link="left_rsen_link"/>
        <origin xyz="0.045 0.065 0.015" rpy="0 0 1.571"/>
    </joint>
    
    <link name="front_rsen_link">
        <visual>
            <geometry>
                <box size="0.014 0.03 0.013" />
            </geometry>
            <origin xyz="0 0 0" rpy="0 0 0" />
            <material name="yellow" />
        </visual>
    </link>   
    
    <joint name="front_rsen_joint" type="fixed">
        <parent link="base_link"/>
        <child link="front_rsen_link"/>
        <origin xyz="0.08 0.0 -0.03" rpy="0 0 0"/>
    </joint>    
    
</robot>
